Workbook

Sheet DATA
A1: STATE | B1: YEAR | C1: INCREMENTAL_LOAD_MW
A2: ARKANSAS | B2: 2026 | C2: 100
A3: ARKANSAS | B3: 2027 | C3: 750
A4: ARKANSAS | B4: 2029 | C4: 93
A5: ARKANSAS | B5: 2030 | C5: 1030
A6: ILLINOIS | B6: 2026 | C6: 104
A7: ILLINOIS | B7: 2028 | C7: 634
A8: INDIANA | B8: 2026 | C8: 666
A9: INDIANA | B9: 2027 | C9: 4228
A10: INDIANA | B10: 2028 | C10: 1730
A11: INDIANA | B11: 2029 | C11: 469
A12: INDIANA | B12: 2030 | C12: 3666
A13: INDIANA | B13: 2031 | C13: 38
... A53: WISCONSIN | B53: 2030 | C53: 3992

Sheet Load growth by state
A3: Row Labels | B3: Sum of INCREMENTAL_LOAD_MW | C3: Sum of INCREMENTAL_LOAD_MW2
A4: ARKANSAS | B4: 1973 | C4: 0.038922097
A5: ILLINOIS | B5: 738 | C5: 0.014558797
A6: INDIANA | B6: 11997 | C6: 0.23666923
A7: IOWA | B7: 5546 | C7: 0.10940798
A8: KENTUCKY | B8: 2282 | C8: 0.045017853
A9: LOUISIANA | B9: 5938 | C9: 0.11714111
A10: MICHIGAN | B10: 3603 | C10: 0.071077706
A11: MINNESOTA | B11: 3058 | C11: 0.060326291
A12: MISSISSIPPI | B12: 2543 | C12: 0.050166696
A13: MISSOURI | B13: 4042 | C13: 0.079738021
A14: NORTH DAKOTA | B14: 2116 | C14: 0.04174311
A15: WISCONSIN | B15: 6855 | C15: 0.13523111
A16: Grand Total | B16: 50691 | C16: 1

Sheet Change Over Time
A3: Row Labels | B3: Sum of INCREMENTAL_LOAD_MW
A4: 2026 | B4: 3136
A5: 2027 | B5: 11449
A6: 2028 | B6: 11611
A7: 2029 | B7: 2948
A8: 2030 | B8: 16509
A9: 2031 | B9: 38
A10: 2032 | B10: 5000
A11: Grand Total | B11: 50691

Sheet Cumulative Load
A3: Row Labels | B3: Sum of INCREMENTAL_LOAD_MW | C3: Cumulative_INCREMENTAL_LOAD_MW2
A4: ARKANSAS | B4: 1973
A5: 2026 | B5: 100 | C5: 100
A6: 2027 | B6: 750 | C6: 850
A7: 2029 | B7: 93 | C7: 943
A8: 2030 | B8: 1030 | C8: 1973
A9: ILLINOIS | B9: 738
A10: 2026 | B10: 104 | C10: 104
A11: 2028 | B11: 634 | C11: 738
A12: INDIANA | B12: 11997
A13: 2026 | B13: 666 | C13: 666
A14: 2027 | B14: 4228 | C14: 4894
A15: 2028 | B15: 1730 | C15: 6624
A16: 2029 | B16: 469 | C16: 7093
A17: 2030 | B17: 3666 | C17: 10759
A18: 2031 | B18: 38 | C18: 10797
A19: 2032 | B19: 1200 | C19: 11997
A20: IOWA | B20: 5546
A21: 2026 | B21: 331 | C21: 331
A22: 2027 | B22: 1121 | C22: 1452
A23: 2028 | B23: 1573 | C23: 3025
A24: 2029 | B24: 162 | C24: 3187
A25: 2030 | B25: 2359 | C25: 5546
A26: KENTUCKY | B26: 2282
A27: 2027 | B27: 241 | C27: 241
A28: 2028 | B28: 241 | C28: 482
A29: 2032 | B29: 1800 | C29: 2282
A30: LOUISIANA | B30: 5938
A31: 2026 | B31: 100 | C31: 100
A32: 2027 | B32: 1268 | C32: 1368
A33: 2028 | B33: 1495 | C33: 2863
A34: 2029 | B34: 945 | C34: 3808
A35: 2030 | B35: 130 | C35: 3938
A36: 2032 | B36: 2000 | C36: 5938
A37: MICHIGAN | B37: 3603
A38: 2026 | B38: 116 | C38: 116
A39: 2027 | B39: 1276 | C39: 1392
A40: 2028 | B40: 1383 | C40: 2775
A41: 2029 | B41: 283 | C41: 3058
A42: 2030 | B42: 545 | C42: 3603
...

Sheet Growth by 2028
A1: YEAR | B1: (Multiple Items)
A3: Row Labels | B3: Sum of INCREMENTAL_LOAD_MW | D3: STATE | E3: Growth by 2028 | F3: Total Growth 2026-2032 | G3: % Arriving by 2028
A4: INDIANA | B4: 6624 | D4: ARKANSAS | E4: =GETPIVOTDATA("INCREMENTAL_LOAD_MW", $A$3, "STATE",D4) -> 850 | F4: =GETPIVOTDATA("Sum of INCREMENTAL_LOAD_MW",'Load growth by state'!$A$3,"STATE",D4) -> 1973 | G4: =E4/F4 -> 0.43081602
A5: IOWA | B5: 3025 | D5: ILLINOIS | E5: =GETPIVOTDATA("INCREMENTAL_LOAD_MW", $A$3, "STATE",D5) -> 738 | F5: =GETPIVOTDATA("Sum of INCREMENTAL_LOAD_MW",'Load growth by state'!$A$3,"STATE",D5) -> 738 | G5: =E5/F5 -> 1
A6: WISCONSIN | B6: 2863 | D6: INDIANA | E6: =GETPIVOTDATA("INCREMENTAL_LOAD_MW", $A$3, "STATE",D6) -> 6624 | F6: =GETPIVOTDATA("Sum of INCREMENTAL_LOAD_MW",'Load growth by state'!$A$3,"STATE",D6) -> 11997 | G6: =E6/F6 -> 0.55213803
A7: LOUISIANA | B7: 2863 | D7: IOWA | E7: =GETPIVOTDATA("INCREMENTAL_LOAD_MW", $A$3, "STATE",D7) -> 3025 | F7: =GETPIVOTDATA("Sum of INCREMENTAL_LOAD_MW",'Load growth by state'!$A$3,"STATE",D7) -> 5546 | G7: =E7/F7 -> 0.54543815
A8: MICHIGAN | B8: 2775 | D8: KENTUCKY | E8: =GETPIVOTDATA("INCREMENTAL_LOAD_MW", $A$3, "STATE",D8) -> 482 | F8: =GETPIVOTDATA("Sum of INCREMENTAL_LOAD_MW",'Load growth by state'!$A$3,"STATE",D8) -> 2282 | G8: =E8/F8 -> 0.21121823
A9: MISSOURI | B9: 2071 | D9: LOUISIANA | E9: =GETPIVOTDATA("INCREMENTAL_LOAD_MW", $A$3, "STATE",D9) -> 2863 | F9: =GETPIVOTDATA("Sum of INCREMENTAL_LOAD_MW",'Load growth by state'!$A$3,"STATE",D9) -> 5938 | G9: =E9/F9 -> 0.48214887
A10: MISSISSIPPI | B10: 1792 | D10: MICHIGAN | E10: =GETPIVOTDATA("INCREMENTAL_LOAD_MW", $A$3, "STATE",D10) -> 2775 | F10: =GETPIVOTDATA("Sum of INCREMENTAL_LOAD_MW",'Load growth by state'!$A$3,"STATE",D10) -> 3603 | G10: =E10/F10 -> 0.77019151
A11: MINNESOTA | B11: 1257 | D11: MINNESOTA | E11: =GETPIVOTDATA("INCREMENTAL_LOAD_MW", $A$3, "STATE",D11) -> 1257 | F11: =GETPIVOTDATA("Sum of INCREMENTAL_LOAD_MW",'Load growth by state'!$A$3,"STATE",D11) -> 3058 | G11: =E11/F11 -> 0.41105298
A12: NORTH DAKOTA | B12: 856 | D12: MISSISSIPPI | E12: =GETPIVOTDATA("INCREMENTAL_LOAD_MW", $A$3, "STATE",D12) -> 1792 | F12: =GETPIVOTDATA("Sum of INCREMENTAL_LOAD_MW",'Load growth by state'!$A$3,"STATE",D12) -> 2543 | G12: =E12/F12 -> 0.70467951
A13: ARKANSAS | B13: 850 | D13: MISSOURI | E13: =GETPIVOTDATA("INCREMENTAL_LOAD_MW", $A$3, "STATE",D13) -> 2071 | F13: =GETPIVOTDATA("Sum of INCREMENTAL_LOAD_MW",'Load growth by state'!$A$3,"STATE",D13) -> 4042 | G13: =E13/F13 -> 0.51237011
A14: ILLINOIS | B14: 738 | D14: NORTH DAKOTA | E14: =GETPIVOTDATA("INCREMENTAL_LOAD_MW", $A$3, "STATE",D14) -> 856 | F14: =GETPIVOTDATA("Sum of INCREMENTAL_LOAD_MW",'Load growth by state'!$A$3,"STATE",D14) -> 2116 | G14: =E14/F14 -> 0.40453686
A15: KENTUCKY | B15: 482 | D15: WISCONSIN | E15: =GETPIVOTDATA("INCREMENTAL_LOAD_MW", $A$3, "STATE",D15) -> 2863 | F15: =GETPIVOTDATA("Sum of INCREMENTAL_LOAD_MW",'Load growth by state'!$A$3,"STATE",D15) -> 6855 | G15: =E15/F15 -> 0.41765135
A16: Grand Total | B16: 26196

Sheet Growth by 2030
A1: YEAR | B1: (Multiple Items)
A3: Row Labels | B3: Sum of INCREMENTAL_LOAD_MW
A4: ARKANSAS | B4: 1973
A5: ILLINOIS | B5: 738
A6: INDIANA | B6: 10759
A7: IOWA | B7: 5546
A8: KENTUCKY | B8: 482
A9: LOUISIANA | B9: 3938
A10: MICHIGAN | B10: 3603
A11: MINNESOTA | B11: 3058
A12: MISSISSIPPI | B12: 2543
A13: MISSOURI | B13: 4042
A14: NORTH DAKOTA | B14: 2116
A15: WISCONSIN | B15: 6855
A16: Grand Total | B16: 45653

Sheet LARGEST YEARLY ADDITIONS
A3: YEAR | B3: STATE | C3: Sum of INCREMENTAL_LOAD_MW | E3: YEAR | F3: STATE | G3: SINGLE-YEAR LOAD ADDITION (MW)
A4: 2030 | B4: WISCONSIN | C4: 3992 | E4: 2027 | F4: INDIANA | G4: 4228
A5: 2030 | B5: INDIANA | C5: 3666 | E5: 2030 | F5: WISCONSIN | G5: 3992
A6: 2030 | B6: IOWA | C6: 2359 | E6: 2030 | F6: INDIANA | G6: 3666
A7: 2030 | B7: MINNESOTA | C7: 1526 | E7: 2030 | F7: IOWA | G7: 2359
A8: 2030 | B8: NORTH DAKOTA | C8: 1260 | E8: 2028 | F8: WISCONSIN | G8: 2273
A9: 2030 | B9: MISSOURI | C9: 1250 | E9: 2032 | F9: LOUISIANA | G9: 2000
A10: 2030 | B10: ARKANSAS | C10: 1030 | E10: 2032 | F10: KENTUCKY | G10: 1800
A11: 2030 | B11: MISSISSIPPI | C11: 751 | E11: 2028 | F11: INDIANA | G11: 1730
A12: 2030 | B12: MICHIGAN | C12: 545 | E12: 2028 | F12: MISSOURI | G12: 1600
A13: 2030 | B13: LOUISIANA | C13: 130 | E13: 2028 | F13: IOWA | G13: 1573
A14: 2028 | B14: WISCONSIN | C14: 2273 | E14: 2030 | F14: MINNESOTA | G14: 1526
A15: 2028 | B15: INDIANA | C15: 1730 | E15: 2028 | F15: LOUISIANA | G15: 1495
... A55: 2031 | B55: INDIANA | C55: 38 | E55: 2031 | F55: INDIANA | G55: 38
A56: Grand Total | C56: 50691
